   self.handle()
  File "/usr/lib/python3/dist-packages/werkzeug/serving.py", line 363, in handle
    super().handle()
  File "/usr/lib/python3.11/http/server.py", line 432, in handle
    self.handle_one_request()
  File "/usr/lib/python3.11/http/server.py", line 420, in handle_one_request
    method()
  File "/usr/lib/python3/dist-packages/werkzeug/serving.py", line 335, in run_wsgi
    execute(self.server.app)
  File "/usr/lib/python3/dist-packages/werkzeug/serving.py", line 324, in execute
    for data in application_iter:
  File "/usr/lib/python3/dist-packages/werkzeug/wsgi.py", line 500, in __next__
    return self._next()
  File "/usr/lib/python3/dist-packages/werkzeug/wrappers/response.py", line 50, in _iter_encoded
    for item in iterable:
  File "/home/Dan/Trilobot-bot/web_control.py", line 305, in generate
    log_info("Starting camera stream generation.")
  File "/home/Dan/Trilobot-bot/debugging.py", line 104, in log_info
    logger.info(message)
Message: 'Starting camera stream generation.'
Arguments: ()
--- Logging error ---
Traceback (most recent call last):
  File "/usr/lib/python3.11/logging/__init__.py", line 1113, in emit
    stream.write(msg + self.terminator)
ValueError: I/O operation on closed file.
Call stack:
  File "/usr/lib/python3.11/threading.py", line 995, in _bootstrap
    self._bootstrap_inner()
  File "/usr/lib/python3.11/threading.py", line 1038, in _bootstrap_inner
    self.run()
  File "/usr/lib/python3.11/threading.py", line 975, in run
    self._target(*self._args, **self._kwargs)
  File "/usr/lib/python3.11/socketserver.py", line 691, in process_request_thread
    self.finish_request(request, client_address)
  File "/usr/lib/python3.11/socketserver.py", line 361, in finish_request
    self.RequestHandlerClass(request, client_address, self)
  File "/usr/lib/python3.11/socketserver.py", line 755, in __init__
    self.handle()
  File "/usr/lib/python3/dist-packages/werkzeug/serving.py", line 363, in handle
    super().handle()
  File "/usr/lib/python3.11/http/server.py", line 432, in handle
    self.handle_one_request()
  File "/usr/lib/python3.11/http/server.py", line 420, in handle_one_request
    method()
  File "/usr/lib/python3/dist-packages/werkzeug/serving.py", line 335, in run_wsgi
    execute(self.server.app)
  File "/usr/lib/python3/dist-packages/werkzeug/serving.py", line 324, in execute
    for data in application_iter:
  File "/usr/lib/python3/dist-packages/werkzeug/wsgi.py", line 500, in __next__
    return self._next()
  File "/usr/lib/python3/dist-packages/werkzeug/wrappers/response.py", line 50, in _iter_encoded
    for item in iterable:
  File "/home/Dan/Trilobot-bot/web_control.py", line 312, in generate
    log_info(f"Using fallback image at: {no_camera_path}")
  File "/home/Dan/Trilobot-bot/debugging.py", line 104, in log_info
    logger.info(message)
Message: 'Using fallback image at: /home/Dan/Trilobot-bot/static/no-camera.png'
Arguments: ()
--- Logging error ---
Traceback (most recent call last):
  File "/usr/lib/python3.11/logging/__init__.py", line 1113, in emit
    stream.write(msg + self.terminator)
ValueError: I/O operation on closed file.
Call stack:
  File "/usr/lib/python3.11/threading.py", line 995, in _bootstrap
    self._bootstrap_inner()
  File "/usr/lib/python3.11/threading.py", line 1038, in _bootstrap_inner
    self.run()
  File "/usr/lib/python3.11/threading.py", line 975, in run
    self._target(*self._args, **self._kwargs)
  File "/usr/lib/python3.11/socketserver.py", line 691, in process_request_thread
    self.finish_request(request, client_address)
  File "/usr/lib/python3.11/socketserver.py", line 361, in finish_request
    self.RequestHandlerClass(request, client_address, self)
  File "/usr/lib/python3.11/socketserver.py", line 755, in __init__
    self.handle()
  File "/usr/lib/python3/dist-packages/werkzeug/serving.py", line 363, in handle
    super().handle()
  File "/usr/lib/python3.11/http/server.py", line 432, in handle
    self.handle_one_request()
  File "/usr/lib/python3.11/http/server.py", line 420, in handle_one_request
    method()
  File "/usr/lib/python3/dist-packages/werkzeug/serving.py", line 335, in run_wsgi
    execute(self.server.app)
  File "/usr/lib/python3/dist-packages/werkzeug/serving.py", line 324, in execute
    for data in application_iter:
  File "/usr/lib/python3/dist-packages/werkzeug/wsgi.py", line 500, in __next__
    return self._next()
  File "/usr/lib/python3/dist-packages/werkzeug/wrappers/response.py", line 50, in _iter_encoded
    for item in iterable:
  File "/home/Dan/Trilobot-bot/web_control.py", line 322, in generate
    log_info(f"Loaded fallback image successfully: {len(fallback_img)} bytes")
  File "/home/Dan/Trilobot-bot/debugging.py", line 104, in log_info
    logger.info(message)
Message: 'Loaded fallback image successfully: 3631 bytes'
Arguments: ()
--- Logging error ---
Traceback (most recent call last):
  File "/usr/lib/python3.11/logging/__init__.py", line 1113, in emit
    stream.write(msg + self.terminator)
ValueError: I/O operation on closed file.
Call stack:
  File "/usr/lib/python3.11/threading.py", line 995, in _bootstrap
    self._bootstrap_inner()
  File "/usr/lib/python3.11/threading.py", line 1038, in _bootstrap_inner
    self.run()
  File "/usr/lib/python3.11/threading.py", line 975, in run
    self._target(*self._args, **self._kwargs)
  File "/usr/lib/python3.11/socketserver.py", line 691, in process_request_thread
    self.finish_request(request, client_address)
  File "/usr/lib/python3.11/socketserver.py", line 361, in finish_request
    self.RequestHandlerClass(request, client_address, self)
  File "/usr/lib/python3.11/socketserver.py", line 755, in __init__
    self.handle()
  File "/usr/lib/python3/dist-packages/werkzeug/serving.py", line 363, in handle
    super().handle()
  File "/usr/lib/python3.11/http/server.py", line 432, in handle
    self.handle_one_request()
  File "/usr/lib/python3.11/http/server.py", line 420, in handle_one_request
    method()
  File "/usr/lib/python3/dist-packages/werkzeug/serving.py", line 335, in run_wsgi
    execute(self.server.app)
  File "/usr/lib/python3/dist-packages/werkzeug/serving.py", line 325, in execute
    write(data)
  File "/usr/lib/python3/dist-packages/werkzeug/serving.py", line 262, in write
    self.send_response(code, msg)
  File "/usr/lib/python3.11/http/server.py", line 497, in send_response
    self.log_request(code)
  File "/usr/lib/python3/dist-packages/werkzeug/serving.py", line 426, in log_request
    self.log("info", '"%s" %s %s', msg, code, size)
  File "/usr/lib/python3/dist-packages/werkzeug/serving.py", line 435, in log
    _log(
  File "/usr/lib/python3/dist-packages/werkzeug/_internal.py", line 224, in _log
    getattr(_logger, type)(message.rstrip(), *args, **kwargs)
Message: '127.0.0.1 - - [14/Apr/2025 23:04:35] "%s" %s %s'
Arguments: ('GET /system_status HTTP/1.1', '200', '-')
--- Logging error ---
Traceback (most recent call last):
  File "/usr/lib/python3.11/logging/__init__.py", line 1113, in emit
    stream.write(msg + self.terminator)
ValueError: I/O operation on closed file.
Call stack:
  File "/usr/lib/python3.11/threading.py", line 995, in _bootstrap
    self._bootstrap_inner()
  File "/usr/lib/python3.11/threading.py", line 1038, in _bootstrap_inner
    self.run()
  File "/usr/lib/python3.11/threading.py", line 975, in run
    self._target(*self._args, **self._kwargs)
  File "/usr/lib/python3.11/socketserver.py", line 691, in process_request_thread
    self.finish_request(request, client_address)
  File "/usr/lib/python3.11/socketserver.py", line 361, in finish_request
    self.RequestHandlerClass(request, client_address, self)
  File "/usr/lib/python3.11/socketserver.py", line 755, in __init__
    self.handle()
  File "/usr/lib/python3/dist-packages/werkzeug/serving.py", line 363, in handle
    super().handle()
  File "/usr/lib/python3.11/http/server.py", line 432, in handle
    self.handle_one_request()
  File "/usr/lib/python3.11/http/server.py", line 420, in handle_one_request
    method()
  File "/usr/lib/python3/dist-packages/werkzeug/serving.py", line 335, in run_wsgi
    execute(self.server.app)
  File "/usr/lib/python3/dist-packages/werkzeug/serving.py", line 325, in execute
    write(data)
  File "/usr/lib/python3/dist-packages/werkzeug/serving.py", line 262, in write
    self.send_response(code, msg)
  File "/usr/lib/python3.11/http/server.py", line 497, in send_response
    self.log_request(code)
  File "/usr/lib/python3/dist-packages/werkzeug/serving.py", line 426, in log_request
    self.log("info", '"%s" %s %s', msg, code, size)
  File "/usr/lib/python3/dist-packages/werkzeug/serving.py", line 435, in log
    _log(
  File "/usr/lib/python3/dist-packages/werkzeug/_internal.py", line 224, in _log
    getattr(_logger, type)(message.rstrip(), *args, **kwargs)
Message: '127.0.0.1 - - [14/Apr/2025 23:04:35] "%s" %s %s'
Arguments: ('GET /stream.mjpg HTTP/1.1', '200', '-')
--- Logging error ---
Traceback (most recent call last):
  File "/usr/lib/python3.11/logging/__init__.py", line 1113, in emit
    stream.write(msg + self.terminator)
ValueError: I/O operation on closed file.
Call stack:
  File "/usr/lib/python3.11/threading.py", line 995, in _bootstrap
    self._bootstrap_inner()
  File "/usr/lib/python3.11/threading.py", line 1038, in _bootstrap_inner
    self.run()
  File "/usr/lib/python3.11/threading.py", line 975, in run
    self._target(*self._args, **self._kwargs)
  File "/usr/lib/python3.11/socketserver.py", line 691, in process_request_thread
    self.finish_request(request, client_address)
  File "/usr/lib/python3.11/socketserver.py", line 361, in finish_request
    self.RequestHandlerClass(request, client_address, self)
  File "/usr/lib/python3.11/socketserver.py", line 755, in __init__
    self.handle()
  File "/usr/lib/python3/dist-packages/werkzeug/serving.py", line 363, in handle
    super().handle()
  File "/usr/lib/python3.11/http/server.py", line 432, in handle
    self.handle_one_request()
  File "/usr/lib/python3.11/http/server.py", line 420, in handle_one_request
    method()
  File "/usr/lib/python3/dist-packages/werkzeug/serving.py", line 335, in run_wsgi
    execute(self.server.app)
  File "/usr/lib/python3/dist-packages/werkzeug/serving.py", line 325, in execute
    write(data)
  File "/usr/lib/python3/dist-packages/werkzeug/serving.py", line 262, in write
    self.send_response(code, msg)
  File "/usr/lib/python3.11/http/server.py", line 497, in send_response
    self.log_request(code)
  File "/usr/lib/python3/dist-packages/werkzeug/serving.py", line 426, in log_request
    self.log("info", '"%s" %s %s', msg, code, size)
  File "/usr/lib/python3/dist-packages/werkzeug/serving.py", line 435, in log
    _log(
  File "/usr/lib/python3/dist-packages/werkzeug/_internal.py", line 224, in _log
    getattr(_logger, type)(message.rstrip(), *args, **kwargs)
Message: '127.0.0.1 - - [14/Apr/2025 23:04:36] "%s" %s %s'
Arguments: ('GET /voice_activity HTTP/1.1', '200', '-')
--- Logging error ---
Traceback (most recent call last):
  File "/usr/lib/python3.11/logging/__init__.py", line 1113, in emit
    stream.write(msg + self.terminator)
ValueError: I/O operation on closed file.
Call stack:
  File "/usr/lib/python3.11/threading.py", line 995, in _bootstrap
    self._bootstrap_inner()
  File "/usr/lib/python3.11/threading.py", line 1038, in _bootstrap_inner
    self.run()
  File "/usr/lib/python3.11/threading.py", line 975, in run
    self._target(*self._args, **self._kwargs)
  File "/usr/lib/python3.11/socketserver.py", line 691, in process_request_thread
    self.finish_request(request, client_address)
  File "/usr/lib/python3.11/socketserver.py", line 361, in finish_request
    self.RequestHandlerClass(request, client_address, self)
  File "/usr/lib/python3.11/socketserver.py", line 755, in __init__
    self.handle()
  File "/usr/lib/python3/dist-packages/werkzeug/serving.py", line 363, in handle
    super().handle()
  File "/usr/lib/python3.11/http/server.py", line 432, in handle
    self.handle_one_request()
  File "/usr/lib/python3.11/http/server.py", line 420, in handle_one_request
    method()
  File "/usr/lib/python3/dist-packages/werkzeug/serving.py", line 335, in run_wsgi
    execute(self.server.app)
  File "/usr/lib/python3/dist-packages/werkzeug/serving.py", line 325, in execute
    write(data)
  File "/usr/lib/python3/dist-packages/werkzeug/serving.py", line 262, in write
    self.send_response(code, msg)
  File "/usr/lib/python3.11/http/server.py", line 497, in send_response
    self.log_request(code)
  File "/usr/lib/python3/dist-packages/werkzeug/serving.py", line 426, in log_request
    self.log("info", '"%s" %s %s', msg, code, size)
  File "/usr/lib/python3/dist-packages/werkzeug/serving.py", line 435, in log
    _log(
  File "/usr/lib/python3/dist-packages/werkzeug/_internal.py", line 224, in _log
    getattr(_logger, type)(message.rstrip(), *args, **kwargs)
Message: '127.0.0.1 - - [14/Apr/2025 23:04:37] "%s" %s %s'
Arguments: ('GET /voice_activity HTTP/1.1', '200', '-')
--- Logging error ---
Traceback (most recent call last):
  File "/usr/lib/python3.11/logging/__init__.py", line 1113, in emit
    stream.write(msg + self.terminator)
ValueError: I/O operation on closed file.
Call stack:
  File "/usr/lib/python3.11/threading.py", line 995, in _bootstrap
    self._bootstrap_inner()
  File "/usr/lib/python3.11/threading.py", line 1038, in _bootstrap_inner
    self.run()
  File "/usr/lib/python3.11/threading.py", line 975, in run
    self._target(*self._args, **self._kwargs)
  File "/usr/lib/python3.11/socketserver.py", line 691, in process_request_thread
    self.finish_request(request, client_address)
  File "/usr/lib/python3.11/socketserver.py", line 361, in finish_request
    self.RequestHandlerClass(request, client_address, self)
  File "/usr/lib/python3.11/socketserver.py", line 755, in __init__
    self.handle()
  File "/usr/lib/python3/dist-packages/werkzeug/serving.py", line 363, in handle
    super().handle()
  File "/usr/lib/python3.11/http/server.py", line 432, in handle
    self.handle_one_request()
  File "/usr/lib/python3.11/http/server.py", line 420, in handle_one_request
    method()
  File "/usr/lib/python3/dist-packages/werkzeug/serving.py", line 335, in run_wsgi
    execute(self.server.app)
  File "/usr/lib/python3/dist-packages/werkzeug/serving.py", line 325, in execute
    write(data)
  File "/usr/lib/python3/dist-packages/werkzeug/serving.py", line 262, in write
    self.send_response(code, msg)
  File "/usr/lib/python3.11/http/server.py", line 497, in send_response
    self.log_request(code)
  File "/usr/lib/python3/dist-packages/werkzeug/serving.py", line 426, in log_request
    self.log("info", '"%s" %s %s', msg, code, size)
  File "/usr/lib/python3/dist-packages/werkzeug/serving.py", line 435, in log
    _log(
  File "/usr/lib/python3/dist-packages/werkzeug/_internal.py", line 224, in _log
    getattr(_logger, type)(message.rstrip(), *args, **kwargs)
Message: '127.0.0.1 - - [14/Apr/2025 23:04:38] "%s" %s %s'
Arguments: ('GET /voice_activity HTTP/1.1', '200', '-')
--- Logging error ---
Traceback (most recent call last):
  File "/usr/lib/python3.11/logging/__init__.py", line 1113, in emit
    stream.write(msg + self.terminator)
ValueError: I/O operation on closed file.
Call stack:
  File "/usr/lib/python3.11/threading.py", line 995, in _bootstrap
    self._bootstrap_inner()
  File "/usr/lib/python3.11/threading.py", line 1038, in _bootstrap_inner
    self.run()
  File "/usr/lib/python3.11/threading.py", line 975, in run
    self._target(*self._args, **self._kwargs)
  File "/usr/lib/python3.11/socketserver.py", line 691, in process_request_thread
    self.finish_request(request, client_address)
  File "/usr/lib/python3.11/socketserver.py", line 361, in finish_request
    self.RequestHandlerClass(request, client_address, self)
  File "/usr/lib/python3.11/socketserver.py", line 755, in __init__
    self.handle()
  File "/usr/lib/python3/dist-packages/werkzeug/serving.py", line 363, in handle
    super().handle()
  File "/usr/lib/python3.11/http/server.py", line 432, in handle
    self.handle_one_request()
  File "/usr/lib/python3.11/http/server.py", line 420, in handle_one_request
    method()
  File "/usr/lib/python3/dist-packages/werkzeug/serving.py", line 335, in run_wsgi
    execute(self.server.app)
  File "/usr/lib/python3/dist-packages/werkzeug/serving.py", line 325, in execute
    write(data)
  File "/usr/lib/python3/dist-packages/werkzeug/serving.py", line 262, in write
    self.send_response(code, msg)
  File "/usr/lib/python3.11/http/server.py", line 497, in send_response
    self.log_request(code)
  File "/usr/lib/python3/dist-packages/werkzeug/serving.py", line 426, in log_request
    self.log("info", '"%s" %s %s', msg, code, size)
  File "/usr/lib/python3/dist-packages/werkzeug/serving.py", line 435, in log
    _log(
  File "/usr/lib/python3/dist-packages/werkzeug/_internal.py", line 224, in _log
    getattr(_logger, type)(message.rstrip(), *args, **kwargs)
Message: '127.0.0.1 - - [14/Apr/2025 23:04:39] "%s" %s %s'
Arguments: ('GET /voice_activity HTTP/1.1', '200', '-')
--- Logging error ---
Traceback (most recent call last):
  File "/usr/lib/python3.11/logging/__init__.py", line 1113, in emit
    stream.write(msg + self.terminator)
ValueError: I/O operation on closed file.
Call stack:
  File "/usr/lib/python3.11/threading.py", line 995, in _bootstrap
    self._bootstrap_inner()
  File "/usr/lib/python3.11/threading.py", line 1038, in _bootstrap_inner
    self.run()
  File "/usr/lib/python3.11/threading.py", line 975, in run
    self._target(*self._args, **self._kwargs)
  File "/usr/lib/python3.11/socketserver.py", line 691, in process_request_thread
    self.finish_request(request, client_address)
  File "/usr/lib/python3.11/socketserver.py", line 361, in finish_request
    self.RequestHandlerClass(request, client_address, self)
  File "/usr/lib/python3.11/socketserver.py", line 755, in __init__
    self.handle()
  File "/usr/lib/python3/dist-packages/werkzeug/serving.py", line 363, in handle
    super().handle()
  File "/usr/lib/python3.11/http/server.py", line 432, in handle
    self.handle_one_request()
  File "/usr/lib/python3.11/http/server.py", line 420, in handle_one_request
    method()
  File "/usr/lib/python3/dist-packages/werkzeug/serving.py", line 335, in run_wsgi
    execute(self.server.app)
  File "/usr/lib/python3/dist-packages/werkzeug/serving.py", line 325, in execute
    write(data)
  File "/usr/lib/python3/dist-packages/werkzeug/serving.py", line 262, in write
    self.send_response(code, msg)
  File "/usr/lib/python3.11/http/server.py", line 497, in send_response
    self.log_request(code)
  File "/usr/lib/python3/dist-packages/werkzeug/serving.py", line 426, in log_request
    self.log("info", '"%s" %s %s', msg, code, size)
  File "/usr/lib/python3/dist-packages/werkzeug/serving.py", line 435, in log
    _log(
  File "/usr/lib/python3/dist-packages/werkzeug/_internal.py", line 224, in _log
    getattr(_logger, type)(message.rstrip(), *args, **kwargs)
Message: '127.0.0.1 - - [14/Apr/2025 23:04:40] "%s" %s %s'
Arguments: ('GET /system_status HTTP/1.1', '200', '-')
--- Logging error ---
Traceback (most recent call last):
  File "/usr/lib/python3.11/logging/__init__.py", line 1113, in emit
    stream.write(msg + self.terminator)
ValueError: I/O operation on closed file.
Call stack:
  File "/usr/lib/python3.11/threading.py", line 995, in _bootstrap
    self._bootstrap_inner()
  File "/usr/lib/python3.11/threading.py", line 1038, in _bootstrap_inner
    self.run()
  File "/usr/lib/python3.11/threading.py", line 975, in run
    self._target(*self._args, **self._kwargs)
  File "/usr/lib/python3.11/socketserver.py", line 691, in process_request_thread
    self.finish_request(request, client_address)
  File "/usr/lib/python3.11/socketserver.py", line 361, in finish_request
    self.RequestHandlerClass(request, client_address, self)
  File "/usr/lib/python3.11/socketserver.py", line 755, in __init__
    self.handle()
  File "/usr/lib/python3/dist-packages/werkzeug/serving.py", line 363, in handle
    super().handle()
  File "/usr/lib/python3.11/http/server.py", line 432, in handle
    self.handle_one_request()
  File "/usr/lib/python3.11/http/server.py", line 420, in handle_one_request
    method()
  File "/usr/lib/python3/dist-packages/werkzeug/serving.py", line 335, in run_wsgi
    execute(self.server.app)
  File "/usr/lib/python3/dist-packages/werkzeug/serving.py", line 325, in execute
    write(data)
  File "/usr/lib/python3/dist-packages/werkzeug/serving.py", line 262, in write
    self.send_response(code, msg)
  File "/usr/lib/python3.11/http/server.py", line 497, in send_response
    self.log_request(code)
  File "/usr/lib/python3/dist-packages/werkzeug/serving.py", line 426, in log_request
    self.log("info", '"%s" %s %s', msg, code, size)
  File "/usr/lib/python3/dist-packages/werkzeug/serving.py", line 435, in log
    _log(
  File "/usr/lib/python3/dist-packages/werkzeug/_internal.py", line 224, in _log
    getattr(_logger, type)(message.rstrip(), *args, **kwargs)
Message: '127.0.0.1 - - [14/Apr/2025 23:04:40] "%s" %s %s'
Arguments: ('GET /voice_activity HTTP/1.1', '200', '-')
--- Logging error ---
Traceback (most recent call last):
  File "/usr/lib/python3.11/logging/__init__.py", line 1113, in emit
    stream.write(msg + self.terminator)
ValueError: I/O operation on closed file.
Call stack:
  File "/usr/lib/python3.11/threading.py", line 995, in _bootstrap
    self._bootstrap_inner()
  File "/usr/lib/python3.11/threading.py", line 1038, in _bootstrap_inner
    self.run()
  File "/usr/lib/python3.11/threading.py", line 975, in run
    self._target(*self._args, **self._kwargs)
  File "/usr/lib/python3.11/socketserver.py", line 691, in process_request_thread
    self.finish_request(request, client_address)
  File "/usr/lib/python3.11/socketserver.py", line 361, in finish_request
    self.RequestHandlerClass(request, client_address, self)
  File "/usr/lib/python3.11/socketserver.py", line 755, in __init__
    self.handle()
  File "/usr/lib/python3/dist-packages/werkzeug/serving.py", line 363, in handle
    super().handle()
  File "/usr/lib/python3.11/http/server.py", line 432, in handle
    self.handle_one_request()
  File "/usr/lib/python3.11/http/server.py", line 420, in handle_one_request
    method()
  File "/usr/lib/python3/dist-packages/werkzeug/serving.py", line 335, in run_wsgi
    execute(self.server.app)
  File "/usr/lib/python3/dist-packages/werkzeug/serving.py", line 325, in execute
    write(data)
  File "/usr/lib/python3/dist-packages/werkzeug/serving.py", line 262, in write
    self.send_response(code, msg)
  File "/usr/lib/python3.11/http/server.py", line 497, in send_response
    self.log_request(code)
  File "/usr/lib/python3/dist-packages/werkzeug/serving.py", line 426, in log_request
    self.log("info", '"%s" %s %s', msg, code, size)
  File "/usr/lib/python3/dist-packages/werkzeug/serving.py", line 435, in log
    _log(
  File "/usr/lib/python3/dist-packages/werkzeug/_internal.py", line 224, in _log
    getattr(_logger, type)(message.rstrip(), *args, **kwargs)
Message: '127.0.0.1 - - [14/Apr/2025 23:04:41] "%s" %s %s'
Arguments: ('GET /voice_activity HTTP/1.1', '200', '-')
--- Logging error ---
Traceback (most recent call last):
  File "/home/Dan/Trilobot-bot/voice_controller.py", line 591, in _recognize_continuously
    text = self.recognizer.recognize_google(audio)
           ^^^^^^^^^^^^^^^^^^^^^^^^^^^^^^^^^^^^^^^
  File "/home/Dan/Trilobot-bot/venv/lib/python3.11/site-packages/speech_recognition/recognizers/google.py", line 262, in recognize_legacy
    return output_parser.parse(response_text)
           ^^^^^^^^^^^^^^^^^^^^^^^^^^^^^^^^^^
  File "/home/Dan/Trilobot-bot/venv/lib/python3.11/site-packages/speech_recognition/recognizers/google.py", line 134, in parse
    actual_result = self.convert_to_result(response_text)
                    ^^^^^^^^^^^^^^^^^^^^^^^^^^^^^^^^^^^^^
  File "/home/Dan/Trilobot-bot/venv/lib/python3.11/site-packages/speech_recognition/recognizers/google.py", line 183, in convert_to_result
    raise UnknownValueError()
speech_recognition.exceptions.UnknownValueError

During handling of the above exception, another exception occurred:

Traceback (most recent call last):
  File "/usr/lib/python3.11/logging/__init__.py", line 1113, in emit
    stream.write(msg + self.terminator)
ValueError: I/O operation on closed file.
Call stack:
  File "/usr/lib/python3.11/threading.py", line 995, in _bootstrap
    self._bootstrap_inner()
  File "/usr/lib/python3.11/threading.py", line 1038, in _bootstrap_inner
    self.run()
  File "/usr/lib/python3.11/threading.py", line 975, in run
    self._target(*self._args, **self._kwargs)
  File "/home/Dan/Trilobot-bot/voice_controller.py", line 598, in _recognize_continuously
    log_warning("Could not understand audio")
  File "/home/Dan/Trilobot-bot/debugging.py", line 112, in log_warning
    logger.warning(message)
Message: 'Could not understand audio'
Arguments: ()
ALSA lib pcm_asym.c:105:(_snd_pcm_asym_open) capture slave is not defined
ALSA lib confmisc.c:1369:(snd_func_refer) Unable to find definition 'cards.0.pcm.front.0:CARD=0'
ALSA lib conf.c:5180:(_snd_config_evaluate) function snd_func_refer returned error: No such file or directory
ALSA lib conf.c:5703:(snd_config_expand) Evaluate error: No such file or directory
ALSA lib pcm.c:2666:(snd_pcm_open_noupdate) Unknown PCM front
ALSA lib pcm.c:2666:(snd_pcm_open_noupdate) Unknown PCM cards.pcm.rear
ALSA lib pcm.c:2666:(snd_pcm_open_noupdate) Unknown PCM cards.pcm.center_lfe
ALSA lib pcm.c:2666:(snd_pcm_open_noupdate) Unknown PCM cards.pcm.side
ALSA lib confmisc.c:1369:(snd_func_refer) Unable to find definition 'cards.0.pcm.surround51.0:CARD=0'
ALSA lib conf.c:5180:(_snd_config_evaluate) function snd_func_refer returned error: No such file or directory
ALSA lib conf.c:5703:(snd_config_expand) Evaluate error: No such file or directory
ALSA lib pcm.c:2666:(snd_pcm_open_noupdate) Unknown PCM surround21
ALSA lib confmisc.c:1369:(snd_func_refer) Unable to find definition 'cards.0.pcm.surround51.0:CARD=0'
ALSA lib conf.c:5180:(_snd_config_evaluate) function snd_func_refer returned error: No such file or directory
ALSA lib conf.c:5703:(snd_config_expand) Evaluate error: No such file or directory
ALSA lib pcm.c:2666:(snd_pcm_open_noupdate) Unknown PCM surround21
ALSA lib confmisc.c:1369:(snd_func_refer) Unable to find definition 'cards.0.pcm.surround40.0:CARD=0'
ALSA lib conf.c:5180:(_snd_config_evaluate) function snd_func_refer returned error: No such file or directory
ALSA lib conf.c:5703:(snd_config_expand) Evaluate error: No such file or directory
ALSA lib pcm.c:2666:(snd_pcm_open_noupdate) Unknown PCM surround40
ALSA lib confmisc.c:1369:(snd_func_refer) Unable to find definition 'cards.0.pcm.surround51.0:CARD=0'
ALSA lib conf.c:5180:(_snd_config_evaluate) function snd_func_refer returned error: No such file or directory
ALSA lib conf.c:5703:(snd_config_expand) Evaluate error: No such file or directory
ALSA lib pcm.c:2666:(snd_pcm_open_noupdate) Unknown PCM surround41
ALSA lib confmisc.c:1369:(snd_func_refer) Unable to find definition 'cards.0.pcm.surround51.0:CARD=0'
ALSA lib conf.c:5180:(_snd_config_evaluate) function snd_func_refer returned error: No such file or directory
ALSA lib conf.c:5703:(snd_config_expand) Evaluate error: No such file or directory
ALSA lib pcm.c:2666:(snd_pcm_open_noupdate) Unknown PCM surround50
ALSA lib confmisc.c:1369:(snd_func_refer) Unable to find definition 'cards.0.pcm.surround51.0:CARD=0'
ALSA lib conf.c:5180:(_snd_config_evaluate) function snd_func_refer returned error: No such file or directory
ALSA lib conf.c:5703:(snd_config_expand) Evaluate error: No such file or directory
ALSA lib pcm.c:2666:(snd_pcm_open_noupdate) Unknown PCM surround51
ALSA lib confmisc.c:1369:(snd_func_refer) Unable to find definition 'cards.0.pcm.surround71.0:CARD=0'
ALSA lib conf.c:5180:(_snd_config_evaluate) function snd_func_refer returned error: No such file or directory
ALSA lib conf.c:5703:(snd_config_expand) Evaluate error: No such file or directory
ALSA lib pcm.c:2666:(snd_pcm_open_noupdate) Unknown PCM surround71
ALSA lib confmisc.c:1369:(snd_func_refer) Unable to find definition 'cards.0.pcm.iec958.0:CARD=0,AES0=4,AES1=130,AES2=0,AES3=2'
ALSA lib conf.c:5180:(_snd_config_evaluate) function snd_func_refer returned error: No such file or directory
ALSA lib conf.c:5703:(snd_config_expand) Evaluate error: No such file or directory
ALSA lib pcm.c:2666:(snd_pcm_open_noupdate) Unknown PCM iec958
ALSA lib confmisc.c:1369:(snd_func_refer) Unable to find definition 'cards.0.pcm.iec958.0:CARD=0,AES0=4,AES1=130,AES2=0,AES3=2'
ALSA lib conf.c:5180:(_snd_config_evaluate) function snd_func_refer returned error: No such file or directory
ALSA lib conf.c:5703:(snd_config_expand) Evaluate error: No such file or directory
ALSA lib pcm.c:2666:(snd_pcm_open_noupdate) Unknown PCM spdif
ALSA lib confmisc.c:1369:(snd_func_refer) Unable to find definition 'cards.0.pcm.iec958.0:CARD=0,AES0=4,AES1=130,AES2=0,AES3=2'
ALSA lib conf.c:5180:(_snd_config_evaluate) function snd_func_refer returned error: No such file or directory
ALSA lib conf.c:5703:(snd_config_expand) Evaluate error: No such file or directory
ALSA lib pcm.c:2666:(snd_pcm_open_noupdate) Unknown PCM spdif
ALSA lib pcm.c:2666:(snd_pcm_open_noupdate) Unknown PCM cards.pcm.modem
ALSA lib pcm.c:2666:(snd_pcm_open_noupdate) Unknown PCM cards.pcm.modem
ALSA lib pcm.c:2666:(snd_pcm_open_noupdate) Unknown PCM cards.pcm.phoneline
ALSA lib pcm.c:2666:(snd_pcm_open_noupdate) Unknown PCM cards.pcm.phoneline
Cannot connect to server socket err = No such file or directory
Cannot connect to server request channel
jack server is not running or cannot be started
JackShmReadWritePtr::~JackShmReadWritePtr - Init not done for -1, skipping unlock
JackShmReadWritePtr::~JackShmReadWritePtr - Init not done for -1, skipping unlock
Cannot connect to server socket err = No such file or directory
Cannot connect to server request channel
jack server is not running or cannot be started
JackShmReadWritePtr::~JackShmReadWritePtr - Init not done for -1, skipping unlock
JackShmReadWritePtr::~JackShmReadWritePtr - Init not done for -1, skipping unlock
ALSA lib pcm_oss.c:397:(_snd_pcm_oss_open) Cannot open device /dev/dsp
ALSA lib pcm_oss.c:397:(_snd_pcm_oss_open) Cannot open device /dev/dsp
--- Logging error ---
Traceback (most recent call last):
  File "/usr/lib/python3.11/logging/__init__.py", line 1113, in emit
    stream.write(msg + self.terminator)
ValueError: I/O operation on closed file.
Call stack:
  File "/usr/lib/python3.11/threading.py", line 995, in _bootstrap
    self._bootstrap_inner()
  File "/usr/lib/python3.11/threading.py", line 1038, in _bootstrap_inner
    self.run()
  File "/usr/lib/python3.11/threading.py", line 975, in run
    self._target(*self._args, **self._kwargs)
  File "/usr/lib/python3.11/socketserver.py", line 691, in process_request_thread
    self.finish_request(request, client_address)
  File "/usr/lib/python3.11/socketserver.py", line 361, in finish_request
    self.RequestHandlerClass(request, client_address, self)
  File "/usr/lib/python3.11/socketserver.py", line 755, in __init__
    self.handle()
  File "/usr/lib/python3/dist-packages/werkzeug/serving.py", line 363, in handle
    super().handle()
  File "/usr/lib/python3.11/http/server.py", line 432, in handle
    self.handle_one_request()
  File "/usr/lib/python3.11/http/server.py", line 420, in handle_one_request
    method()
  File "/usr/lib/python3/dist-packages/werkzeug/serving.py", line 335, in run_wsgi
    execute(self.server.app)
  File "/usr/lib/python3/dist-packages/werkzeug/serving.py", line 325, in execute
    write(data)
  File "/usr/lib/python3/dist-packages/werkzeug/serving.py", line 262, in write
    self.send_response(code, msg)
  File "/usr/lib/python3.11/http/server.py", line 497, in send_response
    self.log_request(code)
  File "/usr/lib/python3/dist-packages/werkzeug/serving.py", line 426, in log_request
    self.log("info", '"%s" %s %s', msg, code, size)
  File "/usr/lib/python3/dist-packages/werkzeug/serving.py", line 435, in log
    _log(
  File "/usr/lib/python3/dist-packages/werkzeug/_internal.py", line 224, in _log
    getattr(_logger, type)(message.rstrip(), *args, **kwargs)
Message: '127.0.0.1 - - [14/Apr/2025 23:04:42] "%s" %s %s'
Arguments: ('GET /voice_activity HTTP/1.1', '200', '-')
ALSA lib pcm_a52.c:1001:(_snd_pcm_a52_open) a52 is only for playback
ALSA lib confmisc.c:1369:(snd_func_refer) Unable to find definition 'cards.0.pcm.iec958.0:CARD=0,AES0=6,AES1=130,AES2=0,AES3=2'
ALSA lib conf.c:5180:(_snd_config_evaluate) function snd_func_refer returned error: No such file or directory
ALSA lib conf.c:5703:(snd_config_expand) Evaluate error: No such file or directory
ALSA lib pcm.c:2666:(snd_pcm_open_noupdate) Unknown PCM iec958:{AES0 0x6 AES1 0x82 AES2 0x0 AES3 0x2 CARD 0}
ALSA lib confmisc.c:160:(snd_config_get_card) Invalid field card
ALSA lib pcm_usb_stream.c:482:(_snd_pcm_usb_stream_open) Invalid card 'card'
ALSA lib confmisc.c:160:(snd_config_get_card) Invalid field card
ALSA lib pcm_usb_stream.c:482:(_snd_pcm_usb_stream_open) Invalid card 'card'
ALSA lib pcm_dmix.c:999:(snd_pcm_dmix_open) unable to open slave
Cannot connect to server socket err = No such file or directory
Cannot connect to server request channel
jack server is not running or cannot be started
JackShmReadWritePtr::~JackShmReadWritePtr - Init not done for -1, skipping unlock
JackShmReadWritePtr::~JackShmReadWritePtr - Init not done for -1, skipping unlock
--- Logging error ---
Traceback (most recent call last):
  File "/usr/lib/python3.11/logging/__init__.py", line 1113, in emit
    stream.write(msg + self.terminator)
ValueError: I/O operation on closed file.
Call stack:
  File "/usr/lib/python3.11/threading.py", line 995, in _bootstrap
    self._bootstrap_inner()
  File "/usr/lib/python3.11/threading.py", line 1038, in _bootstrap_inner
    self.run()
  File "/usr/lib/python3.11/threading.py", line 975, in run
    self._target(*self._args, **self._kwargs)
  File "/usr/lib/python3.11/socketserver.py", line 691, in process_request_thread
    self.finish_request(request, client_address)
  File "/usr/lib/python3.11/socketserver.py", line 361, in finish_request
    self.RequestHandlerClass(request, client_address, self)
  File "/usr/lib/python3.11/socketserver.py", line 755, in __init__
    self.handle()
  File "/usr/lib/python3/dist-packages/werkzeug/serving.py", line 363, in handle
    super().handle()
  File "/usr/lib/python3.11/http/server.py", line 432, in handle
    self.handle_one_request()
  File "/usr/lib/python3.11/http/server.py", line 420, in handle_one_request
    method()
  File "/usr/lib/python3/dist-packages/werkzeug/serving.py", line 335, in run_wsgi
    execute(self.server.app)
  File "/usr/lib/python3/dist-packages/werkzeug/serving.py", line 325, in execute
    write(data)
  File "/usr/lib/python3/dist-packages/werkzeug/serving.py", line 262, in write
    self.send_response(code, msg)
  File "/usr/lib/python3.11/http/server.py", line 497, in send_response
    self.log_request(code)
  File "/usr/lib/python3/dist-packages/werkzeug/serving.py", line 426, in log_request
    self.log("info", '"%s" %s %s', msg, code, size)
  File "/usr/lib/python3/dist-packages/werkzeug/serving.py", line 435, in log
    _log(
  File "/usr/lib/python3/dist-packages/werkzeug/_internal.py", line 224, in _log
    getattr(_logger, type)(message.rstrip(), *args, **kwargs)
Message: '127.0.0.1 - - [14/Apr/2025 23:04:43] "%s" %s %s'
Arguments: ('GET /voice_activity HTTP/1.1', '200', '-')
--- Logging error ---
Traceback (most recent call last):
  File "/usr/lib/python3.11/logging/__init__.py", line 1113, in emit
    stream.write(msg + self.terminator)
ValueError: I/O operation on closed file.
Call stack:
  File "/usr/lib/python3.11/threading.py", line 995, in _bootstrap
    self._bootstrap_inner()
  File "/usr/lib/python3.11/threading.py", line 1038, in _bootstrap_inner
    self.run()
  File "/usr/lib/python3.11/threading.py", line 975, in run
    self._target(*self._args, **self._kwargs)
  File "/usr/lib/python3.11/socketserver.py", line 691, in process_request_thread
    self.finish_request(request, client_address)
  File "/usr/lib/python3.11/socketserver.py", line 361, in finish_request
    self.RequestHandlerClass(request, client_address, self)
  File "/usr/lib/python3.11/socketserver.py", line 755, in __init__
    self.handle()
  File "/usr/lib/python3/dist-packages/werkzeug/serving.py", line 363, in handle
    super().handle()
  File "/usr/lib/python3.11/http/server.py", line 432, in handle
    self.handle_one_request()
  File "/usr/lib/python3.11/http/server.py", line 420, in handle_one_request
    method()
  File "/usr/lib/python3/dist-packages/werkzeug/serving.py", line 335, in run_wsgi
    execute(self.server.app)
  File "/usr/lib/python3/dist-packages/werkzeug/serving.py", line 325, in execute
    write(data)
  File "/usr/lib/python3/dist-packages/werkzeug/serving.py", line 262, in write
    self.send_response(code, msg)
  File "/usr/lib/python3.11/http/server.py", line 497, in send_response
    self.log_request(code)
  File "/usr/lib/python3/dist-packages/werkzeug/serving.py", line 426, in log_request
    self.log("info", '"%s" %s %s', msg, code, size)
  File "/usr/lib/python3/dist-packages/werkzeug/serving.py", line 435, in log
    _log(
  File "/usr/lib/python3/dist-packages/werkzeug/_internal.py", line 224, in _log
    getattr(_logger, type)(message.rstrip(), *args, **kwargs)
Message: '127.0.0.1 - - [14/Apr/2025 23:04:44] "%s" %s %s'
Arguments: ('GET /voice_activity HTTP/1.1', '200', '-')
--- Logging error ---
Traceback (most recent call last):
  File "/usr/lib/python3.11/logging/__init__.py", line 1113, in emit
    stream.write(msg + self.terminator)
ValueError: I/O operation on closed file.
Call stack:
  File "/usr/lib/python3.11/threading.py", line 995, in _bootstrap
    self._bootstrap_inner()
  File "/usr/lib/python3.11/threading.py", line 1038, in _bootstrap_inner
    self.run()
  File "/usr/lib/python3.11/threading.py", line 975, in run
    self._target(*self._args, **self._kwargs)
  File "/usr/lib/python3.11/socketserver.py", line 691, in process_request_thread
    self.finish_request(request, client_address)
  File "/usr/lib/python3.11/socketserver.py", line 361, in finish_request
    self.RequestHandlerClass(request, client_address, self)
  File "/usr/lib/python3.11/socketserver.py", line 755, in __init__
    self.handle()
  File "/usr/lib/python3/dist-packages/werkzeug/serving.py", line 363, in handle
    super().handle()
  File "/usr/lib/python3.11/http/server.py", line 432, in handle
    self.handle_one_request()
  File "/usr/lib/python3.11/http/server.py", line 420, in handle_one_request
    method()
  File "/usr/lib/python3/dist-packages/werkzeug/serving.py", line 335, in run_wsgi
    execute(self.server.app)
  File "/usr/lib/python3/dist-packages/werkzeug/serving.py", line 325, in execute
    write(data)
  File "/usr/lib/python3/dist-packages/werkzeug/serving.py", line 262, in write
    self.send_response(code, msg)
  File "/usr/lib/python3.11/http/server.py", line 497, in send_response
    self.log_request(code)
  File "/usr/lib/python3/dist-packages/werkzeug/serving.py", line 426, in log_request
    self.log("info", '"%s" %s %s', msg, code, size)
  File "/usr/lib/python3/dist-packages/werkzeug/serving.py", line 435, in log
    _log(
  File "/usr/lib/python3/dist-packages/werkzeug/_internal.py", line 224, in _log
    getattr(_logger, type)(message.rstrip(), *args, **kwargs)
Message: '127.0.0.1 - - [14/Apr/2025 23:04:45] "%s" %s %s'
Arguments: ('GET /system_status HTTP/1.1', '200', '-')
--- Logging error ---
Traceback (most recent call last):
  File "/usr/lib/python3.11/logging/__init__.py", line 1113, in emit
    stream.write(msg + self.terminator)
ValueError: I/O operation on closed file.
Call stack:
  File "/usr/lib/python3.11/threading.py", line 995, in _bootstrap
    self._bootstrap_inner()
  File "/usr/lib/python3.11/threading.py", line 1038, in _bootstrap_inner
    self.run()
  File "/usr/lib/python3.11/threading.py", line 975, in run
    self._target(*self._args, **self._kwargs)
  File "/usr/lib/python3.11/socketserver.py", line 691, in process_request_thread
    self.finish_request(request, client_address)
  File "/usr/lib/python3.11/socketserver.py", line 361, in finish_request
    self.RequestHandlerClass(request, client_address, self)
  File "/usr/lib/python3.11/socketserver.py", line 755, in __init__
    self.handle()
  File "/usr/lib/python3/dist-packages/werkzeug/serving.py", line 363, in handle
    super().handle()
  File "/usr/lib/python3.11/http/server.py", line 432, in handle
    self.handle_one_request()
  File "/usr/lib/python3.11/http/server.py", line 420, in handle_one_request
    method()
  File "/usr/lib/python3/dist-packages/werkzeug/serving.py", line 335, in run_wsgi
    execute(self.server.app)
  File "/usr/lib/python3/dist-packages/werkzeug/serving.py", line 325, in execute
    write(data)
  File "/usr/lib/python3/dist-packages/werkzeug/serving.py", line 262, in write
    self.send_response(code, msg)
  File "/usr/lib/python3.11/http/server.py", line 497, in send_response
    self.log_request(code)
  File "/usr/lib/python3/dist-packages/werkzeug/serving.py", line 426, in log_request
    self.log("info", '"%s" %s %s', msg, code, size)
  File "/usr/lib/python3/dist-packages/werkzeug/serving.py", line 435, in log
    _log(
  File "/usr/lib/python3/dist-packages/werkzeug/_internal.py", line 224, in _log
    getattr(_logger, type)(message.rstrip(), *args, **kwargs)
Message: '127.0.0.1 - - [14/Apr/2025 23:04:45] "%s" %s %s'
Arguments: ('GET /voice_activity HTTP/1.1', '200', '-')
--- Logging error ---
Traceback (most recent call last):
  File "/usr/lib/python3.11/logging/__init__.py", line 1113, in emit
    stream.write(msg + self.terminator)
ValueError: I/O operation on closed file.
Call stack:
  File "/usr/lib/python3.11/threading.py", line 995, in _bootstrap
    self._bootstrap_inner()
  File "/usr/lib/python3.11/threading.py", line 1038, in _bootstrap_inner
    self.run()
  File "/usr/lib/python3.11/threading.py", line 975, in run
    self._target(*self._args, **self._kwargs)
  File "/usr/lib/python3.11/socketserver.py", line 691, in process_request_thread
    self.finish_request(request, client_address)
  File "/usr/lib/python3.11/socketserver.py", line 361, in finish_request
    self.RequestHandlerClass(request, client_address, self)
  File "/usr/lib/python3.11/socketserver.py", line 755, in __init__
    self.handle()
  File "/usr/lib/python3/dist-packages/werkzeug/serving.py", line 363, in handle
    super().handle()
  File "/usr/lib/python3.11/http/server.py", line 432, in handle
    self.handle_one_request()
  File "/usr/lib/python3.11/http/server.py", line 420, in handle_one_request
    method()
  File "/usr/lib/python3/dist-packages/werkzeug/serving.py", line 335, in run_wsgi
    execute(self.server.app)
  File "/usr/lib/python3/dist-packages/werkzeug/serving.py", line 325, in execute
    write(data)
  File "/usr/lib/python3/dist-packages/werkzeug/serving.py", line 262, in write
    self.send_response(code, msg)
  File "/usr/lib/python3.11/http/server.py", line 497, in send_response
    self.log_request(code)
  File "/usr/lib/python3/dist-packages/werkzeug/serving.py", line 426, in log_request
    self.log("info", '"%s" %s %s', msg, code, size)
  File "/usr/lib/python3/dist-packages/werkzeug/serving.py", line 435, in log
    _log(
  File "/usr/lib/python3/dist-packages/werkzeug/_internal.py", line 224, in _log
    getattr(_logger, type)(message.rstrip(), *args, **kwargs)
Message: '127.0.0.1 - - [14/Apr/2025 23:04:46] "%s" %s %s'
Arguments: ('GET /voice_activity HTTP/1.1', '200', '-')
--- Logging error ---
Traceback (most recent call last):
  File "/usr/lib/python3.11/logging/__init__.py", line 1113, in emit
    stream.write(msg + self.terminator)
ValueError: I/O operation on closed file.
Call stack:
  File "/usr/lib/python3.11/threading.py", line 995, in _bootstrap
    self._bootstrap_inner()
  File "/usr/lib/python3.11/threading.py", line 1038, in _bootstrap_inner
    self.run()
  File "/usr/lib/python3.11/threading.py", line 975, in run
    self._target(*self._args, **self._kwargs)
  File "/usr/lib/python3.11/socketserver.py", line 691, in process_request_thread
    self.finish_request(request, client_address)
  File "/usr/lib/python3.11/socketserver.py", line 361, in finish_request
    self.RequestHandlerClass(request, client_address, self)
  File "/usr/lib/python3.11/socketserver.py", line 755, in __init__
    self.handle()
  File "/usr/lib/python3/dist-packages/werkzeug/serving.py", line 363, in handle
    super().handle()
  File "/usr/lib/python3.11/http/server.py", line 432, in handle
    self.handle_one_request()
  File "/usr/lib/python3.11/http/server.py", line 420, in handle_one_request
    method()
  File "/usr/lib/python3/dist-packages/werkzeug/serving.py", line 335, in run_wsgi
    execute(self.server.app)
  File "/usr/lib/python3/dist-packages/werkzeug/serving.py", line 325, in execute
    write(data)
  File "/usr/lib/python3/dist-packages/werkzeug/serving.py", line 262, in write
    self.send_response(code, msg)
  File "/usr/lib/python3.11/http/server.py", line 497, in send_response
    self.log_request(code)
  File "/usr/lib/python3/dist-packages/werkzeug/serving.py", line 426, in log_request
    self.log("info", '"%s" %s %s', msg, code, size)
  File "/usr/lib/python3/dist-packages/werkzeug/serving.py", line 435, in log
    _log(
  File "/usr/lib/python3/dist-packages/werkzeug/_internal.py", line 224, in _log
    getattr(_logger, type)(message.rstrip(), *args, **kwargs)
Message: '127.0.0.1 - - [14/Apr/2025 23:04:47] "%s" %s %s'
Arguments: ('GET /voice_activity HTTP/1.1', '200', '-')
--- Logging error ---
Traceback (most recent call last):
  File "/usr/lib/python3.11/logging/__init__.py", line 1113, in emit
    stream.write(msg + self.terminator)
ValueError: I/O operation on closed file.
Call stack:
  File "/usr/lib/python3.11/threading.py", line 995, in _bootstrap
    self._bootstrap_inner()
  File "/usr/lib/python3.11/threading.py", line 1038, in _bootstrap_inner
    self.run()
  File "/usr/lib/python3.11/threading.py", line 975, in run
    self._target(*self._args, **self._kwargs)
  File "/usr/lib/python3.11/socketserver.py", line 691, in process_request_thread
    self.finish_request(request, client_address)
  File "/usr/lib/python3.11/socketserver.py", line 361, in finish_request
    self.RequestHandlerClass(request, client_address, self)
  File "/usr/lib/python3.11/socketserver.py", line 755, in __init__
    self.handle()
  File "/usr/lib/python3/dist-packages/werkzeug/serving.py", line 363, in handle
    super().handle()
  File "/usr/lib/python3.11/http/server.py", line 432, in handle
    self.handle_one_request()
  File "/usr/lib/python3.11/http/server.py", line 420, in handle_one_request
    method()
  File "/usr/lib/python3/dist-packages/werkzeug/serving.py", line 335, in run_wsgi
    execute(self.server.app)
  File "/usr/lib/python3/dist-packages/werkzeug/serving.py", line 325, in execute
    write(data)
  File "/usr/lib/python3/dist-packages/werkzeug/serving.py", line 262, in write
    self.send_response(code, msg)
  File "/usr/lib/python3.11/http/server.py", line 497, in send_response
    self.log_request(code)
  File "/usr/lib/python3/dist-packages/werkzeug/serving.py", line 426, in log_request
    self.log("info", '"%s" %s %s', msg, code, size)
  File "/usr/lib/python3/dist-packages/werkzeug/serving.py", line 435, in log
    _log(
  File "/usr/lib/python3/dist-packages/werkzeug/_internal.py", line 224, in _log
    getattr(_logger, type)(message.rstrip(), *args, **kwargs)
Message: '127.0.0.1 - - [14/Apr/2025 23:04:48] "%s" %s %s'
Arguments: ('GET /voice_activity HTTP/1.1', '200', '-')
^C--- Logging error ---
Traceback (most recent call last):
  File "/usr/lib/python3.11/logging/__init__.py", line 1113, in emit
    stream.write(msg + self.terminator)
ValueError: I/O operation on closed file.
Call stack:
  File "/home/Dan/Trilobot-bot/main.py", line 249, in <module>
    main()
  File "/home/Dan/Trilobot-bot/main.py", line 198, in main
    time.sleep(0.1)
  File "/home/Dan/Trilobot-bot/main.py", line 72, in signal_handler
    log_info("Shutdown signal received")
  File "/home/Dan/Trilobot-bot/debugging.py", line 104, in log_info
    logger.info(message)
Message: 'Shutdown signal received'
Arguments: ()
--- Logging error ---
Traceback (most recent call last):
  File "/usr/lib/python3.11/logging/__init__.py", line 1113, in emit
    stream.write(msg + self.terminator)
ValueError: I/O operation on closed file.
Call stack:
  File "/home/Dan/Trilobot-bot/main.py", line 249, in <module>
    main()
  File "/home/Dan/Trilobot-bot/main.py", line 203, in main
    cleanup()
  File "/home/Dan/Trilobot-bot/main.py", line 207, in cleanup
    log_info("Performing cleanup...")
  File "/home/Dan/Trilobot-bot/debugging.py", line 104, in log_info
    logger.info(message)
Message: 'Performing cleanup...'
Arguments: ()
--- Logging error ---
Traceback (most recent call last):
Traceback (most recent call last):
  File "/home/Dan/Trilobot-bot/main.py", line 249, in <module>
  File "/usr/lib/python3.11/logging/__init__.py", line 1113, in emit
    stream.write(msg + self.terminator)
    main() 
ValueError: I/O operation on closed file.
    ^^^^^^
  File "/home/Dan/Trilobot-bot/main.py", line 203, in main
Call stack:
    cleanup()
  File "/home/Dan/Trilobot-bot/main.py", line 213, in cleanup
  File "/usr/lib/python3.11/threading.py", line 995, in _bootstrap
    self._bootstrap_inner()
  File "/usr/lib/python3.11/threading.py", line 1038, in _bootstrap_inner
    self.run()
  File "/usr/lib/python3.11/threading.py", line 975, in run
    self._target(*self._args, **self._kwargs)
  File "/usr/lib/python3.11/socketserver.py", line 691, in process_request_thread
    self.finish_request(request, client_address)
  File "/usr/lib/python3.11/socketserver.py", line 361, in finish_request
    self.RequestHandlerClass(request, client_address, self)
  File "/usr/lib/python3.11/socketserver.py", line 755, in __init__
    self.handle()
    log_debug("stderr restored")
    ^^^^^^^^^
  File "/usr/lib/python3/dist-packages/werkzeug/serving.py", line 363, in handle
    super().handle()
  File "/usr/lib/python3.11/http/server.py", line 432, in handle
    self.handle_one_request()
NameError: name 'log_debug' is not defined
  File "/usr/lib/python3.11/http/server.py", line 420, in handle_one_request
    method()
  File "/usr/lib/python3/dist-packages/werkzeug/serving.py", line 335, in run_wsgi
    execute(self.server.app)
  File "/usr/lib/python3/dist-packages/werkzeug/serving.py", line 325, in execute
    write(data)
  File "/usr/lib/python3/dist-packages/werkzeug/serving.py", line 262, in write
    self.send_response(code, msg)
  File "/usr/lib/python3.11/http/server.py", line 497, in send_response
    self.log_request(code)
  File "/usr/lib/python3/dist-packages/werkzeug/serving.py", line 426, in log_request
    self.log("info", '"%s" %s %s', msg, code, size)
  File "/usr/lib/python3/dist-packages/werkzeug/serving.py", line 435, in log
    _log(
  File "/usr/lib/python3/dist-packages/werkzeug/_internal.py", line 224, in _log
    getattr(_logger, type)(message.rstrip(), *args, **kwargs)
Message: '127.0.0.1 - - [14/Apr/2025 23:04:49] "%s" %s %s'
Arguments: ('GET /voice_activity HTTP/1.1', '200', '-')
--- Logging error ---
Traceback (most recent call last):
  File "/usr/lib/python3.11/logging/__init__.py", line 1113, in emit
    stream.write(msg + self.terminator)
ValueError: I/O operation on closed file.
Call stack:
  File "/home/Dan/.local/lib/python3.11/site-packages/picamera2/picamera2.py", line 623, in close
    self.stop()
  File "/home/Dan/.local/lib/python3.11/site-packages/picamera2/picamera2.py", line 1239, in stop
    self.stop_()
  File "/home/Dan/.local/lib/python3.11/site-packages/picamera2/picamera2.py", line 1225, in stop_
    _log.info("Camera stopped")
Message: 'Camera stopped'
Arguments: ()
--- Logging error ---
Traceback (most recent call last):
  File "/usr/lib/python3.11/logging/__init__.py", line 1113, in emit
    stream.write(msg + self.terminator)
ValueError: I/O operation on closed file.
Call stack:
  File "/home/Dan/.local/lib/python3.11/site-packages/picamera2/picamera2.py", line 642, in close
    _log.info('Camera closed successfully.')
Message: 'Camera closed successfully.'
Arguments: ()
./run_trilobot.sh: line 42: 25409 Segmentation fault      "$PYTHON_EXEC" "$SCRIPT_DIR/main.py"
Trilobot application finished with exit code: 139
Deactivating virtual environment.
